Workbook

Sheet README
A1: GOVHUB — SAAS METRICS & PROJECTIONS WORKBOOK (v2, rebuilt on real data)
A2: Rebuilt 2026-08-13. Every actual in this file was pulled from a live system and is cited. Nothing is illustrative.
B4: ⚠ WHAT CHANGED FROM v1 — READ THIS FIRST
B5: The July 2026 version of this workbook reported $1,085 MRR, 5 paying customers, 4,250 organic clicks and 10,000 cold
B6: emails sent. None of that was real. It was placeholder data written to demonstrate the formulas, labelled "ILLUSTRATIVE
B7: SAMPLE DATA" in the README, and never overwritten. Taking those numbers into an investor conversation would have been
B8: a serious problem. This version replaces every one of them with a queried, sourced actual.
B10: The honest headline as of 2026-08-13: $0 MRR · 0 paying customers · 0 cold emails sent · 30 signups (9 external).
B11: GovHub is pre-revenue with a built-but-unlaunched acquisition engine. That is a legitimate stage. Overstating it is not.
B13: HOW TO READ THIS WORKBOOK
B14: BLUE cells = hardcoded inputs (an actual you pulled, or a lever you set). BLACK = formulas, do not overwrite.
B15: GREEN = links to another tab. YELLOW fill = the assumptions worth arguing about — the levers.
B16: Actuals tabs run Sep-25 → Aug-26 (Aug-26 is month-to-date through the 13th). Projections run forward from Sep-26.
B17: Every actual carries its source in column B. If a cell has no source, it is a forward assumption, not a fact.
... B44: tier, it is a capacity risk; if it is billed, it is a missing cost line. Expenses row is stubbed at $0 pending your answer.

Sheet Dashboard
A1: EXECUTIVE DASHBOARD — as of 2026-08-13
A2: Pre-revenue. This tab separates what is true, what is moving, and what cannot yet be measured.
A4: WHERE THE BUSINESS ACTUALLY IS
A5: Metric | B5: Value | C5: Prior mo | D5: Δ | E5: Benchmark / target | F5: Status | G5: What it means
A6: MRR | B6: =Revenue!O25 -> 0 | C6: =Revenue!M25 -> 0 | D6: =IF(OR(B6="",C6=""),"",B6-C6) -> 0 | E6: Any positive number | F6: PRE-REVENUE | G6: 0 Stripe subscriptions exist. Not a churn problem — billing has never been switched on.
A7: Paying customers | B7: =Revenue!O16 -> 0 | C7: =Revenue!M16 -> 0 | D7: =IF(OR(B7="",C7=""),"",B7-C7) -> 0 | E7: First 10 = proof | F7: PRE-REVENUE | G7: All 30 accounts are plan_type='trial'.
A8: ARR (run-rate) | B8: =B6*12 -> 0 | C8: =C6*12 -> 0 | D8: =IF(OR(B8="",C8=""),"",B8-C8) -> 0 | E8: — | F8: PRE-REVENUE
A9: Total signups (all-time) | B9: =Funnel!C10 -> 30 | E9: Volume driver | F9: REAL | G9: 30 accounts created since 2025-09.
A10: External signups (all-time) | B10: =Funnel!C11 -> 9 | E10: The number that counts | F10: REAL | G10: 21 of the 30 are founder aliases or test accounts. This is the real top of funnel.
A11: Active trials right now | B11: =Funnel!B30 -> 3 | E11: — | F11: REAL | G11: 26 trials have already expired without a conversion path existing.
A13: WHAT IS ACTUALLY MOVING — the leading indicators
A14: Metric | B14: Now | C14: 60 days ago | D14: Δ | E14: Why it matters | F14: Status | G14: Detail
A15: Organic keywords ranking (top 100) | B15: =SEO!O6 -> 114 | C15: =SEO!L6 -> 1 | D15: =B15-C15 -> 113 | E15: Fastest-moving real asset | F15: STRONG | G15: 1 → 114 in eight weeks. This is the strongest number in the business.
A16: Est. monthly organic sessions | B16: =SEO!O7 -> 20 | C16: =SEO!L7 -> 0 | D16: =B16-C16 -> 20 | E16: Traffic follows keywords | F16: EARLY | G16: Still ~20/mo. Keywords are ranked but deep — position 23 on the big one.
A17: Proposals generated (v2_submissions) | B17: =Funnel!C13 -> 30 | E17: Proof the product runs | F17: REAL | G17: 30 real proposal runs. The product demonstrably works end to end.
A18: Anthropic API spend / mo | B18: =Expenses!N40 -> 7.9 | C18: =Expenses!M40 -> 26.75 | D18: =B18-C18 -> -18.85 | E18: Variable COGS | F18: LOW | G18: $26.75 in the heaviest month. COGS is not the constraint.
A19: Cold emails sent | B19: ='Cold Email'!O8 -> 0 | E19: Channel not yet live | F19: NOT LIVE | G19: 16 domains bought, 12 mailboxes warmed, 3 campaigns drafted, 0 sends.
A21: WHAT CANNOT BE MEASURED YET — and exactly what each one needs
A22: Metric | B22: Status | E22: Blocked on | G22: First honest read available
A23: Trial → paid conversion % | B23: NOT YET MEASURABLE | E23: Stripe billing wired up + first trial cohort passed through it | G23: ~30 days after billing ships
A24: Logo churn / gross MRR churn | B24: NOT YET MEASURABLE | E24: At least one paying cohort with 60+ days of history | G24: ~90 days after first charge
A25: LTV | B25: NOT YET MEASURABLE | E25: A real churn rate. LTV = ARPA × GM% ÷ churn — churn is the input you do not have | G25: ~90 days after first charge
A26: CAC (blended and per channel) | B26: NOT YET MEASURABLE | E26: Paid customers in the denominator. Spend is known; customers are 0 | G26: First 5–10 customers
A27: LTV : CAC and CAC payback | B27: NOT YET MEASURABLE | E27: Both of the above | G27: ~120 days after first charge
A28: Cold email reply / meeting rates | B28: NOT YET MEASURABLE | E28: Campaigns actually sending. Earliest defensible launch is 2026-08-27 | G28: ~2 weeks after launch
A30: THE THREE NUMBERS THAT UNLOCK THIS ENTIRE MODEL
A31: 1. Ship Stripe billing. | B31: Until a price ID exists, trial → paid is 0% by construction. Every unit-economic number in this workbook is blocked behind this one deploy.
A32: 2. Launch cold email on 2026-08-27. | B32: 12 mailboxes × 15–30/day ≈ 5,400 sends/month at full ramp. At benchmark rates that is the first statistically real conversion data you will own.
A33: 3. Move 'govwin' from position 23 into the top 10. | B33: 9,900 monthly searches, already ranked, already 70% of your organic traffic. Position 23 → 8 is roughly a 10–15× click multiple on one page.

Sheet Funnel
A1: ACQUISITION FUNNEL — channel → visitor → signup → activated → engaged → paid
A2: Every stage with its conversion rate off the prior stage. All-time actuals, 2025-09-01 → 2026-08-13.
A4: Read this funnel top to bottom. The conversion column is the rate off the stage directly above it.
A6: WHOLE-BUSINESS FUNNEL (all channels, all time)
A7: Stage | B7: Definition | C7: Count | D7: Conv. from prior | E7: Benchmark | F7: Status | G7: Source
A8: Reach (impressions + emails sent) | B8: Everything that could have seen us | E8: — | G8: NOT PULLED — export total impressions from Search Console and type them here
A9: Visitors (organic sessions) | B9: Landed on www.govhub.online | C9: 41 | D9: =IFERROR(C9/C8,"") | E9: 0.5–2% of impressions | G9: Semrush est. sessions Jul+Aug 2026
A10: Signups (all accounts) | B10: Created an account | C10: 30 | D10: =IFERROR(C10/C9,"") -> 0.73170732 | E10: 0.5–2% of visitors | G10: Supabase user_profiles, deleted_at is null
A11: — of which external | B11: Not a founder alias or test account | C11: 9 | E11: — | G11: Email-domain classification of the 30
A12: Activated | B12: Completed onboarding | C12: 21 | D12: =IFERROR(C12/C10,"") -> 0.7 | E12: 40–60% of signups | G12: user_profiles.onboarding_completed = true
A13: Engaged | B13: Ran ≥1 real proposal (v2_submissions) | C13: 30 | E13: — | G13: v2_submissions, 2026-05 → 2026-08. Runs, not users.
A14: Paid | B14: Has a Stripe subscription | C14: 0 | D14: =IFERROR(C14/C13,"") -> 0 | E14: 10–25% of trials | G14: Supabase subscriptions: 0 rows with a stripe_subscription_id
A16: Overall visitor → paid | D16: =IFERROR(C14/C9,0) -> 0 | E16: Undefined in practice — numerator is 0 because billing does not exist yet.
A18: BY CHANNEL — where the 30 signups actually came from
A19: Channel | B19: Status | C19: Reach | D19: Visitors | E19: Signups | F19: Activated | G19: Paid | H19: Signup→Paid | I19: Note
A20: SEO / organic | B20: LIVE, EARLY | D20: 41 | E20: 1 | F20: 1 | G20: 0 | H20: =IFERROR(G20/E20,0) -> 0 | I20: signup_source='google' first appears 2026-07. Exactly 1 attributable organic signup.
A21: Cold email (Instantly) | B21: NOT LAUNCHED | C21: 0 | D21: 0 | E21: 0 | F21: 0 | G21: 0 | H21: =IFERROR(G21/E21,0) -> 0 | I21: 3 campaigns in Draft, 0 leads, 0 sends. Earliest defensible launch 2026-08-27.
A22: Vendor / PR outreach (Resend) | B22: LIVE | C22: 48 | D22: 0 | E22: 0 | F22: 0 | G22: 0 | H22: =IFERROR(G22/E22,0) -> 0 | I22: 48 vendor emails sent Jul–Aug. No reply/click tracking wired up — see gap below.
A23: Direct / manual / founder-led | B23: LIVE | C23: 0 | D23: 0 | E23: 29 | F23: 20 | G23: 0 | H23: =IFERROR(G23/E23,0) -> 0 | I23: signup_source='manual'. Includes all 21 internal/test accounts and 8 external hand-sourced signups.
A24: TOTAL | C24: =SUM(C20:C23) -> 48 | D24: =SUM(D20:D23) -> 41 | E24: =SUM(E20:E23) -> 30 | F24: =SUM(F20:F23) -> 21 | G24: =SUM(G20:G23) -> 0 | H24: =IFERROR(G24/E24,0) -> 0
A26: TRIAL MECHANICS — what happened to the 30 trials
A27: Metric | B27: Count | C27: % of trials | E27: Note
A28: Trials started (all-time) | B28: 29 | C28: =IFERROR(B28/$B$28,0) -> 1 | E28: First 2025-10-19, most recent 2026-08-11. accounts.trial_start
A29: Trials expired | B29: 26 | C29: =IFERROR(B29/$B$28,0) -> 0.89655172 | E29: trial_end <= now(). Every one of these expired with no way to pay.
A30: Trials active right now | B30: 3 | C30: =IFERROR(B30/$B$28,0) -> 0.10344828 | E30: trial_end > now()
A31: Trials converted to paid | B31: 0 | C31: =IFERROR(B31/$B$28,0) -> 0 | E31: Zero. There is no Stripe price ID to convert against.
A33: MONTHLY TREND — signups, activation and product usage
A34: Metric | B34: Source | C34: Sep-25 | D34: Oct-25 | E34: Nov-25 | F34: Dec-25 | G34: Jan-26 | H34: Feb-26 | I34: Mar-26 | J34: Apr-26 | K34: May-26 | L34: Jun-26 | M34: Jul-26 | N34: Aug-26 | O34: TOTAL / NOW
A35: Signups (all) | B35: Supabase user_profiles | C35: 1 | D35: 11 | E35: 1 | F35: 1 | G35: 0 | H35: 0 | I35: 1 | J35: 0 | K35: 0 | L35: 0 | M35: 12 | N35: 3 | O35: =SUM(C35:N35) -> 30
A36: Signups — external | B36: Non-founder / non-test email | C36: 1 | D36: 2 | E36: 1 | F36: 1 | G36: 0 | H36: 0 | I36: 1 | J36: 0 | K36: 0 | L36: 0 | M36: 3 | N36: 0 | O36: =SUM(C36:N36) -> 9
A37: Signups — internal / test | B37: Founder aliases + QA accounts | C37: 0 | D37: 9 | E37: 0 | F37: 0 | G37: 0 | H37: 0 | I37: 0 | J37: 0 | K37: 0 | L37: 0 | M37: 9 | N37: 3 | O37: =SUM(C37:N37) -> 21
A38: Activated (onboarding complete) | B38: user_profiles.onboarding_completed | C38: 1 | D38: 7 | E38: 0 | F38: 0 | G38: 0 | H38: 0 | I38: 0 | J38: 0 | K38: 0 | L38: 0 | M38: 11 | N38: 2 | O38: =SUM(C38:N38) -> 21
A39: Activation rate | B39: Activated ÷ all signups | C39: =IFERROR(C38/C35,"") -> 1 | D39: =IFERROR(D38/D35,"") -> 0.63636364 | E39: =IFERROR(E38/E35,"") -> 0 | F39: =IFERROR(F38/F35,"") -> 0 | G39: =IFERROR(G38/G35,"") | H39: =IFERROR(H38/H35,"") | I39: =IFERROR(I38/I35,"") -> 0 | J39: =IFERROR(J38/J35,"") | ... O39: =IFERROR(O38/O35,"") -> 0.7
A40: Proposals generated | B40: v2_submissions (runs, not users) | C40: 0 | D40: 0 | E40: 0 | F40: 0 | G40: 0 | H40: 0 | I40: 0 | J40: 0 | K40: 6 | L40: 3 | M40: 16 | N40: 5 | O40: =SUM(C40:N40) -> 30
A41: Lifecycle emails sent | B41: scheduled_emails status='sent' | C41: 0 | D41: 0 | E41: 0 | F41: 0 | G41: 0 | H41: 0 | I41: 0 | J41: 0 | K41: 0 | L41: 19 | M41: 65 | N41: 6 | O41: =SUM(C41:N41) -> 90
A42: Paying customers (ending) | B42: Supabase subscriptions w/ Stripe id | C42: 0 | D42: 0 | E42: 0 | F42: 0 | G42: 0 | H42: 0 | I42: 0 | J42: 0 | K42: 0 | L42: 0 | M42: 0 | N42: 0 | O42: =N42 -> 0

Sheet Calculator
A1: SCENARIO CALCULATOR — conversion rates, pricing, CAC, CLTV
A2: Change any BLUE cell. Everything black recalculates. Yellow = the levers worth arguing about with an investor.
A4: 1 · PRICING & MIX
A5: Solo price ($/mo) | B5: 129 | C5: Live price in plans table
A6: Pro price ($/mo) | B6: 349 | C6: Live price in plans table
A7: Team price ($/mo) | B7: 699 | C7: Live price in plans table
A8: Mix — Solo % | B8: 0.6 | C8: Assumption: SMB-heavy govcon ICP
A9: Mix — Pro % | B9: 0.32
A10: Mix — Team % | B10: 0.08
A11: Mix check (must = 100%) | B11: =B8+B9+B10 -> 1 | C11: =IF(ROUND(B11,4)=1,"OK","FIX MIX") -> OK
A12: Blended ARPA ($/mo) | B12: =B5*B8+B6*B9+B7*B10 -> 245 | C12: Weighted average revenue per account
A13: Annual-plan share of new customers % | B13: 0.2 | C13: Annual = 10× monthly in the plans table (2 months free)
A14: Annual discount (implied) | B14: 0.1667 | C14: 1 - 10/12
A15: Effective ARPA after annual discount | B15: =B12*(1-B13*B14) -> 236.8317 | C15: This is the ARPA used everywhere below
A17: 2 · FUNNEL — SEO / ORGANIC
A18: Monthly organic sessions | B18: 41 | C18: Actual Jul+Aug 2026 (Semrush est.)
A19: Session → signup % | B19: 0.025 | C19: Benchmark 0.5–2%; you are early and low-traffic
A20: Signup → activated % | B20: 0.7 | C20: Actual all-time: 70% (21/30)
A21: Activated → paid % | B21: 0.12 | C21: ASSUMPTION — no actual exists. Benchmark 10–25%
A22: → Signups / mo | B22: =B18*B19 -> 1.025
A23: → Activated / mo | B23: =B22*B20 -> 0.7175
A24: → New customers / mo (SEO) | B24: =B23*B21 -> 0.0861
A26: 3 · FUNNEL — COLD EMAIL
A27: Mailboxes sending | B27: 12 | C27: Wave 1: 12 mailboxes across 12 domains
A28: Sends per mailbox per day | B28: 15 | C28: Instantly daily cap; 50–100 only after months of history
A29: Sending days per month | B29: 22 | C29: Weekdays only
A30: → Emails sent / mo | B30: =B27*B28*B29 -> 3960
A31: Bounce rate % | B31: 0.02 | C31: Keep <2% — MillionVerifier is the control here
A32: → Delivered / mo | B32: =B30*(1-B31) -> 3880.8
A33: Reply rate % (of delivered) | B33: 0.034 | C33: 2026 industry avg ~3.4%
A34: Positive share of replies % | B34: 0.33 | C34: Rest are 'remove me' / not-now
A35: Positive reply → meeting % | B35: 0.42
A36: Meeting → trial % | B36: 0.65
A37: Trial → paid % (email) | B37: 0.3 | C37: Higher intent than organic — they spoke to you
A38: → Replies / mo | B38: =B32*B33 -> 131.9472
A39: → Positive replies / mo | B39: =B38*B34 -> 43.542576
A40: → Meetings / mo | B40: =B39*B35 -> 18.287882
A41: → Trials / mo | B41: =B40*B36 -> 11.887123
A42: → New customers / mo (email) | B42: =B41*B37 -> 3.566137
A44: 4 · FUNNEL — DIRECT / REFERRAL / FOUNDER-LED
...

Sheet Revenue
A1: REVENUE & CUSTOMERS — actuals
A2: All zeros, and that is the correct number. 0 rows in subscriptions carry a stripe_subscription_id.
A4: Prices below are live values from the Supabase plans table, read 2026-08-13.
A6: PRICE LIST (source: plans table)
A7: Trial | B7: $0/mo · $0/yr · 3 proposals/mo | C7: stripe_price_id: NULL — cannot be charged
A8: Solo | B8: $129/mo · $1290/yr · 3 proposals/mo | C8: stripe_price_id: NULL — cannot be charged
A9: Pro | B9: $349/mo · $3490/yr · 15 proposals/mo | C9: stripe_price_id: NULL — cannot be charged
A10: Team | B10: $699/mo · $6990/yr · 50 proposals/mo | C10: stripe_price_id: NULL — cannot be charged
A12: CUSTOMER MOVEMENT
A13: Metric | B13: Source | C13: Sep-25 | D13: Oct-25 | E13: Nov-25 | F13: Dec-25 | G13: Jan-26 | H13: Feb-26 | I13: Mar-26 | J13: Apr-26 | K13: May-26 | L13: Jun-26 | M13: Jul-26 | N13: Aug-26 | O13: TOTAL / NOW
A14: New customers | B14: Supabase subscriptions | C14: 0 | D14: 0 | E14: 0 | F14: 0 | G14: 0 | H14: 0 | I14: 0 | J14: 0 | K14: 0 | L14: 0 | M14: 0 | N14: 0 | O14: =SUM(C14:N14) -> 0
A15: Churned customers | B15: Supabase subscriptions | C15: 0 | D15: 0 | E15: 0 | F15: 0 | G15: 0 | H15: 0 | I15: 0 | J15: 0 | K15: 0 | L15: 0 | M15: 0 | N15: 0 | O15: =SUM(C15:N15) -> 0
A16: Ending customers | B16: Cumulative | C16: 0 | D16: 0 | E16: 0 | F16: 0 | G16: 0 | H16: 0 | I16: 0 | J16: 0 | K16: 0 | L16: 0 | M16: 0 | N16: 0 | O16: =N16 -> 0
A18: MRR WATERFALL
A19: Beginning MRR | C19: 0 | D19: 0 | E19: 0 | F19: 0 | G19: 0 | H19: 0 | I19: 0 | J19: 0 | K19: 0 | L19: 0 | M19: 0 | N19: 0 | O19: =N19 -> 0
A20: New business MRR | B20: Stripe | C20: 0 | D20: 0 | E20: 0 | F20: 0 | G20: 0 | H20: 0 | I20: 0 | J20: 0 | K20: 0 | L20: 0 | M20: 0 | N20: 0 | O20: =SUM(C20:N20) -> 0
A21: Expansion MRR | B21: Stripe | C21: 0 | D21: 0 | E21: 0 | F21: 0 | G21: 0 | H21: 0 | I21: 0 | J21: 0 | K21: 0 | L21: 0 | M21: 0 | N21: 0 | O21: =SUM(C21:N21) -> 0
A22: Contraction MRR | B22: Stripe | C22: 0 | D22: 0 | E22: 0 | F22: 0 | G22: 0 | H22: 0 | I22: 0 | J22: 0 | K22: 0 | L22: 0 | M22: 0 | N22: 0 | O22: =SUM(C22:N22) -> 0
A23: Churned MRR | B23: Stripe | C23: 0 | D23: 0 | E23: 0 | F23: 0 | G23: 0 | H23: 0 | I23: 0 | J23: 0 | K23: 0 | L23: 0 | M23: 0 | N23: 0 | O23: =SUM(C23:N23) -> 0
A24: Net new MRR | C24: 0 | D24: 0 | E24: 0 | F24: 0 | G24: 0 | H24: 0 | I24: 0 | J24: 0 | K24: 0 | L24: 0 | M24: 0 | N24: 0 | O24: =SUM(C24:N24) -> 0
A25: Ending MRR | C25: 0 | D25: 0 | E25: 0 | F25: 0 | G25: 0 | H25: 0 | I25: 0 | J25: 0 | K25: 0 | L25: 0 | M25: 0 | N25: 0 | O25: =N25 -> 0
A26: ARR (run-rate) | B26: Ending MRR × 12 | C26: 0 | D26: 0 | E26: 0 | F26: 0 | G26: 0 | H26: 0 | I26: 0 | J26: 0 | K26: 0 | L26: 0 | M26: 0 | N26: 0 | O26: =N26 -> 0
A28: When the first charge lands, overwrite these rows from the Stripe dashboard. Every ratio in this workbook that currently reads 0 or 'never' will start returning a real number.

Sheet SEO
A1: MARKETING — SEO / ORGANIC (real data)
A2: Sources: Semrush us database (pulled 2026-08-13) and Google Search Console (property verified 2026-06-20).
A4: VISIBILITY
A5: Metric | B5: Source | C5: Sep-25 | D5: Oct-25 | E5: Nov-25 | F5: Dec-25 | G5: Jan-26 | H5: Feb-26 | I5: Mar-26 | J5: Apr-26 | K5: May-26 | L5: Jun-26 | M5: Jul-26 | N5: Aug-26 | O5: TOTAL / NOW
A6: Organic keywords (top 100) | B6: Semrush resource_rank_history | C6: 0 | D6: 0 | E6: 0 | F6: 1 | G6: 1 | H6: 0 | I6: 0 | J6: 0 | K6: 1 | L6: 1 | M6: 90 | N6: 114 | O6: =N6 -> 114
A7: Est. organic sessions / mo | B7: Semrush organic traffic estimate | C7: 0 | D7: 0 | E7: 0 | F7: 0 | G7: 0 | H7: 0 | I7: 0 | J7: 0 | K7: 0 | L7: 0 | M7: 21 | N7: 20 | O7: =N7 -> 20
A8: GSC clicks (28-day trailing) | B8: GSC milestone notifications — fill monthly | C8: 0 | D8: 0 | E8: 0 | F8: 0 | G8: 0 | H8: 0 | I8: 0 | J8: 0 | K8: 0 | L8: 0 | M8: 15 | O8: =N8 -> 0
A9: Est. traffic value ($/mo) | B9: Semrush organic cost | C9: 0 | D9: 0 | E9: 0 | F9: 0 | G9: 0 | H9: 0 | I9: 0 | J9: 0 | K9: 0 | L9: 0 | M9: 94 | N9: 241 | O9: =N9 -> 241
A11: Semrush shows 1 keyword and 0 traffic every month from Dec-25 to Jun-26. The site went from 1 → 90 keywords in July and 90 → 114 in August. That inflection is real and it is the best number in this workbook.
A13: TOP ORGANIC KEYWORDS (Semrush, 2026-08-13)
A14: Keyword | B14: Position | C14: Volume | D14: CPC | E14: % of traffic | F14: Landing page
A15: govwin | B15: 23 | C15: 9900 | D15: 12.59 | E15: 0.7 | F15: /vs/govwin-iq/
A16: gov hub | B16: 7 | C16: 140 | D16: 10.48 | E16: 0.05 | F16: /
A17: govwin iq pricing | B17: 14 | C17: 260 | D17: 14.4 | E17: 0.05 | F17: /vs/govwin-iq/
A18: responsive io alternative | B18: 29 | C18: 140 | D18: 0 | E18: 0 | F18: /alternatives/responsive/
A19: what does idiq stand for in government contracting | B19: 19 | C19: 70 | D19: 0 | E19: 0 | F19: /glossary/idiq/
A20: cage number sam gov | B20: 31 | C20: 40 | D20: 2.29 | E20: 0 | F20: /glossary/cage-code/
A21: govtribe pricing | B21: 40 | C21: 90 | D21: 5.57 | E21: 0 | F21: /pricing/
A22: govwin subscription cost | B22: 58 | C22: 110 | D22: 7.67 | E22: 0 | F22: /pricing/
A23: rfp | B23: 70 | C23: 40500 | D23: 3.99 | E23: 0 | F23: /glossary/rfp/
A24: how to write a government proposal | B24: 71 | C24: 110 | D24: 4.45 | E24: 0 | F24: /blog/how-to-write-a-government-proposal/
A26: THE SINGLE HIGHEST-LEVERAGE SEO FACT IN THIS FILE
A27: 'govwin' — 9,900 searches/month, $12.59 CPC — is ranked at position 23 and already produces 70% of your organic traffic from page 3. Position 23 → 8 is roughly a 10–15× click multiple on that one page. Nothing else on this tab is worth doing first.
A29: ORGANIC FUNNEL & COST
A30: Metric | B30: Source / note | C30: Sep-25 | D30: Oct-25 | E30: Nov-25 | F30: Dec-25 | G30: Jan-26 | H30: Feb-26 | I30: Mar-26 | J30: Apr-26 | K30: May-26 | L30: Jun-26 | M30: Jul-26 | N30: Aug-26 | O30: TOTAL / NOW
A31: Organic signups | B31: user_profiles.signup_source='google' | C31: 0 | D31: 0 | E31: 0 | F31: 0 | G31: 0 | H31: 0 | I31: 0 | J31: 0 | K31: 0 | L31: 0 | M31: 1 | N31: 0 | O31: =SUM(C31:N31) -> 1
A32: Organic new customers | B32: Supabase subscriptions | C32: 0 | D32: 0 | E32: 0 | F32: 0 | G32: 0 | H32: 0 | I32: 0 | J32: 0 | K32: 0 | L32: 0 | M32: 0 | N32: 0 | O32: =SUM(C32:N32) -> 0
A33: SEO spend ($) | B33: Content produced in-house — no cash cost booked | C33: 0 | D33: 0 | E33: 0 | F33: 0 | G33: 0 | H33: 0 | I33: 0 | J33: 0 | K33: 0 | L33: 0 | M33: 0 | N33: 0 | O33: =SUM(C33:N33) -> 0
A34: Session → signup % | B34: Signups ÷ est. sessions | C34: =IFERROR(C31/C7,"") | D34: =IFERROR(D31/D7,"") | E34: =IFERROR(E31/E7,"") | F34: =IFERROR(F31/F7,"") | G34: =IFERROR(G31/G7,"") | H34: =IFERROR(H31/H7,"") | I34: =IFERROR(I31/I7,"") | J34: =IFERROR(J31/J7,"") | ... O34: =IFERROR(O31/O7,"") -> 0.05

Sheet Cold Email
A1: MARKETING — COLD EMAIL (built, not launched)
A2: Source: govhub-marketing/docs/instantly-wave1.md, campaign state 2026-08-12. Zero emails have been sent.
A4: STATUS: 3 campaigns created 2026-08-12, all in Draft with zero leads. Nothing sends until leads are uploaded and campaigns started.
A6: ACTUALS
A7: Metric | B7: Source | C7: Sep-25 | D7: Oct-25 | E7: Nov-25 | F7: Dec-25 | G7: Jan-26 | H7: Feb-26 | I7: Mar-26 | J7: Apr-26 | K7: May-26 | L7: Jun-26 | M7: Jul-26 | N7: Aug-26 | O7: TOTAL / NOW
A8: Cold emails sent | B8: Instantly — campaigns in Draft | C8: 0 | D8: 0 | E8: 0 | F8: 0 | G8: 0 | H8: 0 | I8: 0 | J8: 0 | K8: 0 | L8: 0 | M8: 0 | N8: 0 | O8: =SUM(C8:N8) -> 0
A9: Replies | B9: n/a — nothing sent | C9: 0 | D9: 0 | E9: 0 | F9: 0 | G9: 0 | H9: 0 | I9: 0 | J9: 0 | K9: 0 | L9: 0 | M9: 0 | N9: 0 | O9: =SUM(C9:N9) -> 0
A10: Meetings booked | B10: n/a — nothing sent | C10: 0 | D10: 0 | E10: 0 | F10: 0 | G10: 0 | H10: 0 | I10: 0 | J10: 0 | K10: 0 | L10: 0 | M10: 0 | N10: 0 | O10: =SUM(C10:N10) -> 0
A11: New customers from cold email | B11: n/a — nothing sent | C11: 0 | D11: 0 | E11: 0 | F11: 0 | G11: 0 | H11: 0 | I11: 0 | J11: 0 | K11: 0 | L11: 0 | M11: 0 | N11: 0 | O11: =SUM(C11:N11) -> 0
A12: Sending domains owned | B12: 16 purchased 2026-08-06 | C12: 0 | D12: 0 | E12: 0 | F12: 0 | G12: 0 | H12: 0 | I12: 0 | J12: 0 | K12: 0 | L12: 0 | M12: 0 | N12: 16 | O12: =N12 -> 16
A13: Mailboxes warmed (wave 1) | B13: 12 live, warmup score 100 | C13: 0 | D13: 0 | E13: 0 | F13: 0 | G13: 0 | H13: 0 | I13: 0 | J13: 0 | K13: 0 | L13: 0 | M13: 0 | N13: 12 | O13: =N13 -> 12
A15: SEPARATE MOTION — vendor / PR outreach via Resend (this one IS sending)
A16: Metric | B16: Source | C16: Sep-25 | D16: Oct-25 | E16: Nov-25 | F16: Dec-25 | G16: Jan-26 | H16: Feb-26 | I16: Mar-26 | J16: Apr-26 | K16: May-26 | L16: Jun-26 | M16: Jul-26 | N16: Aug-26 | O16: TOTAL / NOW
A17: Vendor outreach emails sent | B17: govhub-marketing/data/vendor-outreach.json | C17: 0 | D17: 0 | E17: 0 | F17: 0 | G17: 0 | H17: 0 | I17: 0 | J17: 0 | K17: 0 | L17: 0 | M17: 10 | N17: 38 | O17: =SUM(C17:N17) -> 48
A19: 48 vendor emails have gone out (43 of 91 ledger rows have no contact found). There is no open, click or reply tracking on this motion — so its contribution to the funnel is currently unmeasurable. Wiring Resend webhooks into the email_events table (0 rows today) would fix that cheaply.
A21: LAUNCH READINESS
A22: Item | B22: State | C22: Note
A23: Domains purchased | B23: 16 (2026-08-06) | C23: $141 first year, $10/yr each on renewal
A24: Mailboxes warmed | B24: 12, warmup score 100 | C24: ~54 warmup emails each — that is not a sending history
A25: Campaigns built | B25: 3 (A serial_bidder, B new_prime, C registered_no_awards) | C25: All Draft, 0 leads
A26: Leads uploaded | B26: 0 | C26: THE BLOCKER — nothing sends without these
A27: Earliest defensible launch | B27: 2026-08-27 | C27: Day 21 from domain creation. Day 30 (2026-09-05) is safer
A28: Schedule backstop | B28: start_date 2026-08-27 | C28: An accidental activation still sends nothing before this date
A30: CAPACITY MODEL — what this engine produces once it is running
A31: Live from the Calculator tab. Change the levers there, not here.
A32: Stage | B32: Per month | C32: Rate used
A33: Emails sent | B33: =Calculator!B30 -> 3960 | C33: =Calculator!B27&" mailboxes × "&Calculator!B28&"/day × "&Calculator!B29&" days" -> 12 mailboxes × 15/day × 22 days
A34: Delivered | B34: =Calculator!B32 -> 3880.8 | C34: =TEXT(1-Calculator!B31,"0.0%")&" deliverability" -> 98.0% deliverability
A35: Replies | B35: =Calculator!B38 -> 131.9472 | C35: =TEXT(Calculator!B33,"0.0%")&" reply rate" -> 3.4% reply rate
A36: Positive replies | B36: =Calculator!B39 -> 43.542576 | C36: =TEXT(Calculator!B34,"0.0%")&" of replies positive" -> 33.0% of replies positive
A37: Meetings | B37: =Calculator!B40 -> 18.287882 | C37: =TEXT(Calculator!B35,"0.0%")&" positive → meeting" -> 42.0% positive → meeting
A38: Trials | B38: =Calculator!B41 -> 11.887123 | C38: =TEXT(Calculator!B36,"0.0%")&" meeting → trial" -> 65.0% meeting → trial
A39: New customers | B39: =Calculator!B42 -> 3.566137 | C39: =TEXT(Calculator!B37,"0.0%")&" trial → paid" -> 30.0% trial → paid

Sheet Expenses
A1: EXPENSES — cost stack, run-rate and burn
A2: Cost stack provided by the founder 2026-08-13. Anthropic API is real spend from v2_token_usage.
A4: THE COST STACK — current run-rate
A5: Vendor / item | B5: Billing | C5: $ / month | D5: $ / year | E5: Category | F5: Status | G5: Note
A6: Claude (subscription) | B6: $100.00 / month | C6: 100 | D6: =C6*12 -> 1200 | E6: Operational | F6: Fixed | G6: Founder-provided
A7: Anthropic API | B7: usage-based | C7: =N40 -> 7.9 | D7: =C7*12 -> 94.8 | E7: Operational | F7: Variable | G7: Actual: $0.19 Jun · $26.75 Jul · $7.90 Aug MTD. Cell links to the trailing month.
A8: OpenAI / ChatGPT API | B8: usage-based | C8: 0 | D8: =C8*12 -> 0 | E8: Operational | F8: Variable | G8: Founder-provided as variable. No spend figure supplied — enter actuals here.
A9: Resend | B9: $20.00 / month | C9: 20 | D9: =C9*12 -> 240 | E9: Operational | F9: Fixed | G9: Founder-provided
A10: Cloudflare | B10: $5.00 / month | C10: 5 | D10: =C10*12 -> 60 | E10: Operational | F10: Fixed | G10: Founder-provided
A11: govhub.online (main domain) | B11: $40.00 / year | C11: =D11/12 -> 3.3333333 | D11: 40 | E11: Operational | F11: Annual | G11: Renews 9/26 every year. Monthly figure is the $40 amortised.
A12: Supabase | B12: unknown | C12: 0 | D12: =C12*12 -> 0 | E12: Operational | F12: OPEN ITEM | G12: NOT in the founder's cost list, but GovProp is ACTIVE_HEALTHY in production. Confirm tier.
A13: Subtotal — Operational | C13: =SUM(C6:C12) -> 136.23333 | D13: =SUM(D6:D12) -> 1634.8
A15: Postiz | B15: $29.00 / month | C15: 29 | D15: =C15*12 -> 348 | E15: Marketing | F15: Fixed | G15: Founder-provided
A16: Instantly.ai | B16: $99.00 / month | C16: 99 | D16: =C16*12 -> 1188 | E16: Marketing | F16: Fixed | G16: Founder-provided
A17: Apollo | B17: $59.00 / month | C17: 59 | D17: =C17*12 -> 708 | E17: Marketing | F17: Fixed | G17: Founder-provided. May drop to $0 or rise to $159 — see scenario note below.
A18: MillionVerifier | B18: $59.00 / month | C18: 59 | D18: =C18*12 -> 708 | E18: Marketing | F18: Fixed | G18: Founder-provided
A19: Cold email domains (16) | B19: $141.00 first year | C19: =D19/12 -> 11.75 | D19: 141 | E19: Marketing | F19: Annual | G19: $141 year 1 (bought 2026-08-06); renews at $10.00/yr each = $160.00/yr.
A20: Subtotal — Marketing | C20: =SUM(C15:C19) -> 257.75 | D20: =SUM(D15:D19) -> 3093
A22: TOTAL MONTHLY BURN (run-rate) | C22: =C13+C20 -> 393.98333 | D22: =D13+D20 -> 4727.8 | G22: Operational + Marketing. Anthropic API is already inside the Operational subtotal at the trailing month's actual — it is not added again here.
A23: Cash cost excluding founder time | G23: No salary, contractor or founder-time cost is booked anywhere in this workbook. See the CAC warning on the Calculator tab before quoting any CAC or LTV:CAC number.
A25: ANNUAL RENEWAL CALENDAR
A26: Item | B26: Amount | C26: Next due | D26: Then | E26: Note
A27: govhub.online | B27: 40 | C27: 2026-09-26 | D27: $40.00 every 9/26 | E27: Main product domain
A28: 16 cold email domains | B28: 160 | C28: 2027-08-06 | D28: $160.00/yr | E28: $141.00 was the year-1 promo; renewal is $10.00 × 16
A30: APOLLO SCENARIO — the one cost line you flagged as uncertain
A31: Scenario | B31: Apollo $/mo | C31: Total burn $/mo | D31: Δ vs today | E31: Note
A32: Today (as instructed) | B32: 59 | C32: =$C$22-$C$17+B32 -> 393.98333 | D32: =C32-$C$22 -> 0 | E32: Current run-rate
A33: Apollo dropped | B33: 0 | C33: =$C$22-$C$17+B33 -> 334.98333 | D33: =C33-$C$22 -> -59 | E33: You find a cheaper email-finding source
A34: Apollo +$100 | B34: 159 | C34: =$C$22-$C$17+B34 -> 493.98333 | D34: =C34-$C$22 -> 100 | E34: No alternative found, tier upgrade required
A37: MONTHLY ACTUALS
A38: Only Anthropic API has a queried actual per month. The subscription rows are seeded at the current run-rate for Aug-26 — fill earlier months from card statements if you want a true historical burn.
A39: Cost line | B39: Source | C39: Sep-25 | D39: Oct-25 | E39: Nov-25 | F39: Dec-25 | G39: Jan-26 | H39: Feb-26 | I39: Mar-26 | J39: Apr-26 | K39: May-26 | L39: Jun-26 | M39: Jul-26 | N39: Aug-26 | O39: TOTAL / NOW
A40: Anthropic API | B40: v2_token_usage.est_cost_usd | C40: 0 | D40: 0 | E40: 0 | F40: 0 | G40: 0 | H40: 0 | I40: 0 | J40: 0 | K40: 0 | L40: 0.19 | M40: 26.75 | N40: 7.9 | O40: =SUM(C40:N40) -> 34.84
A41: Claude subscription | B41: Founder-provided run-rate | N41: 100 | O41: =SUM(C41:N41) -> 100
A42: Resend | B42: Founder-provided run-rate | N42: 20 | O42: =SUM(C42:N42) -> 20
A43: Cloudflare | B43: Founder-provided run-rate | N43: 5 | O43: =SUM(C43:N43) -> 5
A44: Postiz | B44: Founder-provided run-rate | N44: 29 | O44: =SUM(C44:N44) -> 29
A45: Instantly.ai | B45: Founder-provided run-rate | N45: 99 | O45: =SUM(C45:N45) -> 99
A46: Apollo | B46: Founder-provided run-rate | N46: 59 | O46: =SUM(C46:N46) -> 59
A47: MillionVerifier | B47: Founder-provided run-rate | N47: 59 | O47: =SUM(C47:N47) -> 59
...

Sheet Unit Economics
A1: UNIT ECONOMICS
A2: Nearly every number here is blocked on the same thing: a first paying customer. This tab says so explicitly.
A4: Metric | B4: Actual today | C4: At Calculator's assumptions | D4: Benchmark | E4: Status | H4: What it needs to become real
A5: New customers / mo | B5: 0 | C5: =Calculator!B61 -> 4.152237 | D5: — | E5: REAL | H5: Actual is 0 because there is no billing path.
A6: Effective ARPA | B6: 0 | C6: =Calculator!B15 -> 236.8317 | D6: — | E6: REAL | H6: Modelled from the live price list × an assumed tier mix.
A7: Total S&M spend / mo | B7: =Expenses!C20 -> 257.75 | C7: =Calculator!B63 -> 5257.75 | D7: — | E7: REAL | H7: Real: the marketing subtotal from the Expenses tab.
A8: Blended CAC | B8: n/a | C8: =Calculator!B64 -> 1266.2452 | D8: Judge vs LTV only | E8: MODELLED | H8: Needs paying customers in the denominator. Spend is known; customers are 0.
A9: Gross margin % | B9: n/a | C9: =Calculator!B52 -> 0.85 | D9: 75–85% | E9: MODELLED | H9: API cost is trivially small, so 85% is a defensible modelling assumption.
A10: Monthly churn % | B10: n/a | C10: =Calculator!B50 -> 0.05 | D10: SMB 3–7% | E10: MODELLED | H10: Needs one paying cohort with 60+ days of history.
A11: LTV (GM-adjusted) | B11: n/a | C11: =Calculator!B67 -> 4026.1389 | D11: — | E11: MODELLED | H11: ARPA × GM% ÷ churn. Blocked entirely on a real churn rate.
A12: LTV : CAC | B12: n/a | C12: =Calculator!B68 -> 3.1795888 | D12: ≥3x healthy, 5x+ strong | E12: MODELLED | H12: Blocked on both LTV and CAC.
A13: CAC payback (months) | B13: n/a | C13: =Calculator!B69 -> 6.2901216 | D13: ≤12 months | E13: MODELLED | H13: Annual prepay would shorten this materially — 20% annual share is already modelled.
A14: Steady-state MRR ceiling | B14: n/a | C14: =Calculator!B70 -> 19667.627 | D14: — | E14: MODELLED | H14: New MRR ÷ churn. The number this engine converges to. Worth knowing before you scale spend.
A16: Column B is what you can defend with data today. Column C is what the model produces at the Calculator's assumptions. Never present column C as though it were column B — that is exactly the mistake the previous version of this workbook made.

Sheet Projections
A1: PROJECTIONS — 24-month driver model (Sep-26 → Aug-28)
A2: Every driver is a live link to the Calculator tab. Change levers there; this tab follows.
A4: Cold email is modelled as launching in Sep-26 (first full month after the 2026-08-27 earliest defensible start). SEO clicks compound at the growth rate below.
A6: DRIVERS (live from Calculator)
A7: Organic sessions, month 1 | B7: =Calculator!B18 -> 41
A8: Monthly session growth % | B8: 0.15
A9: Session → signup % | B9: =Calculator!B19 -> 0.025
A10: Signup → activated % | B10: =Calculator!B20 -> 0.7
A11: Activated → paid % | B11: =Calculator!B21 -> 0.12
A12: Emails sent / mo (at full ramp) | B12: =Calculator!B30 -> 3960
A13: Email sends growth % | B13: 0.05
A14: Email → customer conversion % | B14: =IFERROR(Calculator!B42/Calculator!B30,0) -> 0.00090053964
A15: Direct customers / mo | B15: =Calculator!B47 -> 0.5
A16: Effective ARPA | B16: =Calculator!B15 -> 236.8317
A17: Monthly churn % | B17: =Calculator!B50 -> 0.05
A18: Monthly expansion % | B18: =Calculator!B51 -> 0.01
A19: Gross margin % | B19: =Calculator!B52 -> 0.85
A20: Fixed cost / mo | B20: =Expenses!C22+Calculator!B56 -> 5393.9833
A21: Monthly cost growth % | B21: 0.02
A23: MODEL
A24: Line | C24: Sep-26 | D24: Oct-26 | E24: Nov-26 | F24: Dec-26 | G24: Jan-27 | H24: Feb-27 | I24: Mar-27 | J24: Apr-27 | K24: May-27 | L24: Jun-27 | M24: Jul-27 | N24: Aug-27 | O24: Sep-27 | P24: Oct-27 | Q24: Nov-27 | R24: Dec-27 | S24: Jan-28 | T24: Feb-28 | U24: Mar-28 | V24: Apr-28 | W24: May-28 | X24: Jun-28 | Y24: Jul-28 | Z24: Aug-28
A25: Organic sessions | C25: =$B$7 -> 41 | D25: =C25*(1+$B$8) -> 47.15 | E25: =D25*(1+$B$8) -> 54.2225 | F25: =E25*(1+$B$8) -> 62.355875 | G25: =F25*(1+$B$8) -> 71.709256 | H25: =G25*(1+$B$8) -> 82.465645 | I25: =H25*(1+$B$8) -> 94.835491 | J25: =I25*(1+$B$8) -> 109.06082 | K25: =J25*(1+$B$8) -> 125.41994 | ... Z25: =Y25*(1+$B$8) -> 1020.5498
A26: Organic signups | C26: =C25*$B$9 -> 1.025 | D26: =D25*$B$9 -> 1.17875 | E26: =E25*$B$9 -> 1.3555625 | F26: =F25*$B$9 -> 1.5588969 | G26: =G25*$B$9 -> 1.7927314 | H26: =H25*$B$9 -> 2.0616411 | I26: =I25*$B$9 -> 2.3708873 | J26: =J25*$B$9 -> 2.7265204 | ... Z26: =Z25*$B$9 -> 25.513744
A27: Organic activated | C27: =C26*$B$10 -> 0.7175 | D27: =D26*$B$10 -> 0.825125 | E27: =E26*$B$10 -> 0.94889375 | F27: =F26*$B$10 -> 1.0912278 | G27: =G26*$B$10 -> 1.254912 | H27: =H26*$B$10 -> 1.4431488 | I27: =I26*$B$10 -> 1.6596211 | J27: =J26*$B$10 -> 1.9085643 | ... Z27: =Z26*$B$10 -> 17.859621
A28: New customers — SEO | C28: =C27*$B$11 -> 0.0861 | D28: =D27*$B$11 -> 0.099015 | E28: =E27*$B$11 -> 0.11386725 | F28: =F27*$B$11 -> 0.13094734 | G28: =G27*$B$11 -> 0.15058944 | H28: =H27*$B$11 -> 0.17317785 | I28: =I27*$B$11 -> 0.19915453 | J28: =J27*$B$11 -> 0.22902771 | ... Z28: =Z27*$B$11 -> 2.1431545
A29: Emails sent | C29: =$B$12 -> 3960 | D29: =C29*(1+$B$13) -> 4158 | E29: =D29*(1+$B$13) -> 4365.9 | F29: =E29*(1+$B$13) -> 4584.195 | G29: =F29*(1+$B$13) -> 4813.4047 | H29: =G29*(1+$B$13) -> 5054.075 | I29: =H29*(1+$B$13) -> 5306.7787 | J29: =I29*(1+$B$13) -> 5572.1177 | K29: =J29*(1+$B$13) -> 5850.7236 | ... Z29: =Y29*(1+$B$13) -> 12163.234
A30: New customers — cold email | C30: =C29*$B$14 -> 3.566137 | D30: =D29*$B$14 -> 3.7444438 | E30: =E29*$B$14 -> 3.931666 | F30: =F29*$B$14 -> 4.1282493 | G30: =G29*$B$14 -> 4.3346618 | H30: =H29*$B$14 -> 4.5513949 | I30: =I29*$B$14 -> 4.7789646 | J30: =J29*$B$14 -> 5.0179128 | ... Z30: =Z29*$B$14 -> 10.953474
A31: New customers — direct | C31: =$B$15 -> 0.5 | D31: =$B$15 -> 0.5 | E31: =$B$15 -> 0.5 | F31: =$B$15 -> 0.5 | G31: =$B$15 -> 0.5 | H31: =$B$15 -> 0.5 | I31: =$B$15 -> 0.5 | J31: =$B$15 -> 0.5 | ... Z31: =$B$15 -> 0.5
A32: Total new customers | C32: =C28+C30+C31 -> 4.152237 | D32: =D28+D30+D31 -> 4.3434588 | E32: =E28+E30+E31 -> 4.5455333 | F32: =F28+F30+F31 -> 4.7591967 | G32: =G28+G30+G31 -> 4.9852512 | H32: =H28+H30+H31 -> 5.2245727 | I32: =I28+I30+I31 -> 5.4781191 | J32: =J28+J30+J31 -> 5.7469406 | ... Z32: =Z28+Z30+Z31 -> 13.596629
A34: Beginning customers | C34: =0 -> 0 | D34: =C36 -> 4.152237 | E34: =D36 -> 8.2880839 | F34: =E36 -> 12.419213 | G34: =F36 -> 16.557449 | H34: =G36 -> 20.714828 | I34: =H36 -> 24.903659 | J34: =I36 -> 29.136595 | K34: =J36 -> 33.426706 | ... Z34: =Y36 -> 116.08386
A35: Churned customers | C35: =C34*$B$17 -> 0 | D35: =D34*$B$17 -> 0.20761185 | E35: =E34*$B$17 -> 0.4144042 | F35: =F34*$B$17 -> 0.62096065 | G35: =G34*$B$17 -> 0.82787245 | H35: =H34*$B$17 -> 1.0357414 | I35: =I34*$B$17 -> 1.245183 | J35: =J34*$B$17 -> 1.4568298 | ... Z35: =Z34*$B$17 -> 5.8041932
A36: Ending customers | C36: =C34+C32-C35 -> 4.152237 | D36: =D34+D32-D35 -> 8.2880839 | E36: =E34+E32-E35 -> 12.419213 | F36: =F34+F32-F35 -> 16.557449 | G36: =G34+G32-G35 -> 20.714828 | H36: =H34+H32-H35 -> 24.903659 | I36: =I34+I32-I35 -> 29.136595 | J36: =J34+J32-J35 -> 33.426706 | ... Z36: =Z34+Z32-Z35 -> 123.8763
A38: Beginning MRR | C38: =0 -> 0 | D38: =C43 -> 983.38134 | E38: =D43 -> 1972.7148 | F38: =E43 -> 2970.3326 | G38: =F43 -> 3978.6479 | H38: =G43 -> 5000.1675 | I38: =H43 -> 6037.5053 | J38: =I43 -> 7093.3973 | K38: =J43 -> 8170.7191 | ... Z38: =Y43 -> 29586.093
A39: New MRR | C39: =C32*$B$16 -> 983.38134 | D39: =D32*$B$16 -> 1028.6687 | E39: =E32*$B$16 -> 1076.5264 | F39: =F32*$B$16 -> 1127.1286 | G39: =G32*$B$16 -> 1180.6655 | H39: =H32*$B$16 -> 1237.3444 | I39: =I32*$B$16 -> 1297.3923 | J39: =J32*$B$16 -> 1361.0577 | ... Z39: =Z32*$B$16 -> 3220.1127
A40: Expansion MRR | C40: =C38*$B$18 -> 0 | D40: =D38*$B$18 -> 9.8338134 | E40: =E38*$B$18 -> 19.727148 | F40: =F38*$B$18 -> 29.703326 | G40: =G38*$B$18 -> 39.786479 | H40: =H38*$B$18 -> 50.001675 | I40: =I38*$B$18 -> 60.375053 | J40: =J38*$B$18 -> 70.933973 | ... Z40: =Z38*$B$18 -> 295.86093
A41: Churned MRR | C41: =C38*$B$17 -> 0 | D41: =D38*$B$17 -> 49.169067 | E41: =E38*$B$17 -> 98.635741 | F41: =F38*$B$17 -> 148.51663 | G41: =G38*$B$17 -> 198.9324 | H41: =H38*$B$17 -> 250.00838 | I41: =I38*$B$17 -> 301.87526 | J41: =J38*$B$17 -> 354.66987 | ... Z41: =Z38*$B$17 -> 1479.3046
A42: Net new MRR | C42: =C39+C40-C41 -> 983.38134 | D42: =D39+D40-D41 -> 989.33348 | E42: =E39+E40-E41 -> 997.61778 | F42: =F39+F40-F41 -> 1008.3153 | G42: =G39+G40-G41 -> 1021.5196 | H42: =H39+H40-H41 -> 1037.3377 | I42: =I39+I40-I41 -> 1055.8921 | J42: =J39+J40-J41 -> 1077.3218 | ... Z42: =Z39+Z40-Z41 -> 2036.669
A43: Ending MRR | C43: =C38+C42 -> 983.38134 | D43: =D38+D42 -> 1972.7148 | E43: =E38+E42 -> 2970.3326 | F43: =F38+F42 -> 3978.6479 | G43: =G38+G42 -> 5000.1675 | H43: =H38+H42 -> 6037.5053 | I43: =I38+I42 -> 7093.3973 | J43: =J38+J42 -> 8170.7191 | ... Z43: =Z38+Z42 -> 31622.762
A44: ARR (run-rate) | C44: =C43*12 -> 11800.576 | D44: =D43*12 -> 23672.578 | E44: =E43*12 -> 35643.991 | F44: =F43*12 -> 47743.775 | G44: =G43*12 -> 60002.01 | H44: =H43*12 -> 72450.063 | I44: =I43*12 -> 85120.768 | J44: =J43*12 -> 98048.63 | ... Z44: =Z43*12 -> 379473.14
A46: Gross profit | C46: =C43*$B$19 -> 835.87414 | D46: =D43*$B$19 -> 1676.8076 | E46: =E43*$B$19 -> 2524.7827 | F46: =F43*$B$19 -> 3381.8507 | G46: =G43*$B$19 -> 4250.1424 | H46: =H43*$B$19 -> 5131.8795 | I46: =I43*$B$19 -> 6029.3877 | J46: =J43*$B$19 -> 6945.1113 | ... Z46: =Z43*$B$19 -> 26879.348
...

Sheet Benchmarks
A1: BENCHMARKS & TARGETS — what good looks like
A2: Compiled from David Skok (forEntrepreneurs/Matrix), David Sacks (Craft Ventures), OpenView, and 2026 cold-email datasets.
A4: Category | B4: Metric | C4: Benchmark / target | D4: Why it matters / how it applies to GovHub
A5: Growth | B5: MRR growth (MoM) | C5: 10%+ strong pre-$1M ARR | D5: Best single proof of product-market fit. Not measurable at $0.
A6: Growth | B6: Net New MRR mix | C6: New + expansion > churn + contraction | D6: Track the four-part waterfall from the first paying month.
A7: Retention | B7: Logo churn (monthly) | C7: SMB SaaS 3–7%/mo; aim <5% | D7: Govcon has bid-cycle seasonality — expect lumpy early churn.
A8: Retention | B8: Net revenue retention | C8: ≥100% | D8: Solo→Pro upgrades and Team seats are the expansion path.
A9: Retention | B9: Quick ratio | C9: ≥4x | D9: (New+Expansion) ÷ (Churned+Contraction). <2 = leaky bucket.
A10: Unit economics | B10: LTV : CAC | C10: ≥3x healthy; 5x+ strong | D10: Skok/Craft standard. <3x means do not scale spend yet.
A11: Unit economics | B11: CAC payback | C11: ≤12 months | D11: Annual prepay (10× monthly) shortens effective payback materially.
A12: Unit economics | B12: Gross margin | C12: 75–85% | D12: Your API cost is ~$27/mo at peak — margin is not your problem.
A13: Unit economics | B13: Magic number | C13: >0.75 = step on gas; <0.5 = fix first | D13: Net-new ARR ÷ prior-period S&M.
A14: Unit economics | B14: Rule of 40 | C14: Growth% + margin% ≥ 40 | D14: Matters past $1M ARR; directional before that.
A15: Funnel | B15: Trial → paid (no card) | C15: ~10–25% typical band | D15: The Calculator assumes 12% organic / 30% email. Both are assumptions.
... A28: Cash | B28: Runway | C28: ≥12 months | D28: At ~$413/mo burn this is governed by your personal runway, not the company's.
